<?xml version="1.0" ?>
<robot name="IndyDualArm" xmlns:xacro="http://www.ros.org/wiki/xacro">
  <material name="metal_grey">
    <color rgba="0.5 0.5 0.5 1"/>
  </material>
  <material name="metal_white_grey">
    <color rgba="0.7 0.7 0.7 1"/>
  </material>  
	<link name="world"/>
	<link name="body">
		<inertial>
			<origin rpy="0 0 0" xyz="0 0 0"/>
			<mass value="1.59306955" />
			<inertia ixx="+0.00572623" iyy="+0.00558959" izz="+0.00966674" ixy="+0.00000251" iyz="-0.00000014" ixz="-0.00011380"/>
		</inertial>
		<visual>
			<origin rpy="0 0 0" xyz="0 0 0"/>
			<geometry>
				<mesh filename="meshes/dual_arm_body.stl"/>
			</geometry>
		<material name="metal_grey"/>

		</visual>
		<collision>
			<origin rpy="0 0 0" xyz="0 0 0.11461"/>
			<geometry>
				<box size="0.4 0.6 0.22922" />
			</geometry>
		</collision>
		<collision>
			<origin rpy="0 0 0" xyz="0 0 0.22922"/>
	     <geometry>
	        <sphere radius="0.23"/>
      </geometry>		
		</collision>
	</link>
	
	<link name="r_0">
		<inertial>
			<origin rpy="0 0 0" xyz="0.00131966  -0.00000218  0.03212832"/>
			<mass value="1.6703078"/>
			<inertia ixx="+0.00661309" ixy="+0.00000183" ixz="+0.00002695" iyy="+0.00644765" iyz="-0.00000027" izz="+0.00792090"/>
		</inertial>
		<visual>
			<origin rpy="0 0 0" xyz="0 0 0"/>
			<geometry>
				<mesh filename="meshes/visual/Indy7_0.stl"/>
			</geometry>
	        <material name="metal_grey"/>

		</visual>
		<collision>
			<origin rpy="0 0 0" xyz="0 0 0"/>
			<geometry>
				<mesh filename="meshes/collision/Indy7_0.stl"/>
			</geometry>
		</collision>

	</link>
		<link name="r_1">
		 <inertial>
			<origin rpy="0 0 0" xyz="-0.00023749  -0.04310313  0.13245396"/>
			<mass value="11.44444535"/>
			<inertia ixx="+0.35065005" ixy="+0.00011931" ixz="-0.00037553" iyy="+0.30479800" iyz="-0.10984447" izz="+0.06003147"/>
			</inertial>
		<visual>
			<origin rpy="0 0 0" xyz="0 0 0"/>
			<geometry>
				<mesh filename="meshes/visual/Indy7_1.stl"/>
			</geometry>
		</visual>
		<collision>
			<origin rpy="0 0 0" xyz="0 0 0"/>
			<geometry>
				<mesh filename="meshes/collision/Indy7_1.stl"/>
			</geometry>
		</collision>
	</link>
	<link name="r_2">
		 <inertial>
			<origin rpy="0 0 0" xyz="-0.29616699 0.00002254 0.04483069"/>
			<mass value="5.84766553"/>
			<inertia ixx="+0.03599743" ixy="-0.00004693" ixz="-0.05240346" iyy="+0.72293306" iyz="+0.00000176" izz="+0.70024119"/>
			</inertial>
		<visual>
			<origin rpy="0 0 0" xyz="0 0 0"/>
			<geometry>
				<mesh filename="meshes/visual/Indy7_2.stl"/>
			</geometry>
		</visual>
		<collision>
			<origin rpy="0 0 0" xyz="0 0 0"/>
			<geometry>
				<mesh filename="meshes/collision/Indy7_2.stl"/>
			</geometry>
		</collision>
	</link>
	<link name="r_3">
	   <inertial>
		<origin rpy="0 0 0" xyz="-0.16804016 0.00021421 -0.07000383"/>
		<mass value="2.68206064"/>
		<inertia ixx="+0.01617210" ixy="-0.00011817" ixz="+0.03341882" iyy="+0.11364055" iyz="-0.00004371" izz="+0.10022522"/>
		</inertial>
		<visual>
			<origin rpy="0 0 0" xyz="0 0 0"/>
			<geometry>
				<mesh filename="meshes/visual/Indy7_3.stl"/>
			</geometry>
		</visual>
		<collision>
			<origin rpy="0 0 0" xyz="0 0 0"/>
			<geometry>
				<mesh filename="meshes/collision/Indy7_3.stl"/>
			</geometry>
		</collision>
	</link>
	<link name="r_4">
  <inertial>
      <origin rpy="0 0 0" xyz="-0.00026847 -0.07098440 0.07649128"/>
      <mass value="2.12987371"/>
      <inertia ixx="+0.02798891" ixy="+0.00003893" ixz="-0.00004768" iyy="+0.01443076" iyz="-0.01266296" izz="+0.01496211"/>
    </inertial>
		<visual>
			<origin rpy="0 0 0" xyz="0 0 0"/>
			<geometry>
				<mesh filename="meshes/visual/Indy7_4.stl"/>
			</geometry>
		</visual>
		<collision>
			<origin rpy="0 0 0" xyz="0 0 0"/>
			<geometry>
				<mesh filename="meshes/collision/Indy7_4.stl"/>
			</geometry>
		</collision>
	</link>
	<link name="r_5">
    <inertial>
      <origin rpy="0 0 0" xyz="-0.09796232 -0.00023114 0.06445892"/>
      <mass value="2.22412271"/>
      <inertia ixx="+0.01105297" ixy="+0.00005517" ixz="-0.01481977" iyy="+0.03698291" iyz="-0.00003740" izz="+0.02754795"/>
    </inertial>
		<visual>
			<origin rpy="0 0 0" xyz="0 0 0"/>
			<geometry>
				<mesh filename="meshes/visual/Indy7_5.stl"/>
			</geometry>
		</visual>
		<collision>
			<origin rpy="0 0 0" xyz="0 0 0"/>
			<geometry>
				<mesh filename="meshes/collision/Indy7_5.stl"/>
			</geometry>
		</collision>
	</link>
	<link name="r_6">
   <inertial>
      <origin rpy="0 0 0" xyz="0.00008147 -0.00046556 0.03079097"/>
      <mass value="0.38254932"/>
      <inertia ixx="+0.00078982" ixy="-0.00000034" ixz="+0.00000083" iyy="+0.00079764" iyz="-0.00000508" izz="+0.00058319"/>
    </inertial>
		<visual>
			<origin rpy="0 0 0" xyz="0 0 0"/>
			<geometry>
				<mesh filename="meshes/visual/Indy7_6.stl"/>
			</geometry>
		</visual>
		<collision>
			<origin rpy="0 0 0" xyz="0 0 0"/>
			<geometry>
				<mesh filename="meshes/collision/Indy7_6.stl"/>
			</geometry>
		</collision>
	</link>
	<link name="l_0">
	    <inertial>
      <origin rpy="0 0 0" xyz="0.00131966  -0.00000218  0.03212832"/>
      <mass value="1.6703078"/>
      <inertia ixx="+0.00661309" ixy="+0.00000183" ixz="+0.00002695" iyy="+0.00644765" iyz="-0.00000027" izz="+0.00792090"/>
    </inertial>
		<visual>
			<origin rpy="0 0 0" xyz="0 0 0"/>
			<geometry>
				<mesh filename="meshes/visual/Indy7_0.stl"/>
			</geometry>
	        <material name="metal_grey"/>

		</visual>
		<collision>
			<origin rpy="0 0 0" xyz="0 0 0"/>
			<geometry>
				<mesh filename="meshes/collision/Indy7_0.stl"/>
			</geometry>
		</collision>

	</link>
		<link name="l_1">
	   <inertial>
      <origin rpy="0 0 0" xyz="-0.00023749  -0.04310313  0.13245396"/>
      <mass value="11.44444535"/>
      <inertia ixx="+0.35065005" ixy="+0.00011931" ixz="-0.00037553" iyy="+0.30479800" iyz="-0.10984447" izz="+0.06003147"/>
    </inertial>
		<visual>
			<origin rpy="0 0 0" xyz="0 0 0"/>
			<geometry>
				<mesh filename="meshes/visual/Indy7_1.stl"/>
			</geometry>
		</visual>
		<collision>
			<origin rpy="0 0 0" xyz="0 0 0"/>
			<geometry>
				<mesh filename="meshes/collision/Indy7_1.stl"/>
			</geometry>
		</collision>
	</link>
	<link name="l_2">
	   <inertial>
      <origin rpy="0 0 0" xyz="-0.29616699 0.00002254 0.04483069"/>
      <mass value="5.84766553"/>
      <inertia ixx="+0.03599743" ixy="-0.00004693" ixz="-0.05240346" iyy="+0.72293306" iyz="+0.00000176" izz="+0.70024119"/>
    </inertial>
		<visual>
			<origin rpy="0 0 0" xyz="0 0 0"/>
			<geometry>
				<mesh filename="meshes/visual/Indy7_2.stl"/>
			</geometry>
		</visual>
		<collision>
			<origin rpy="0 0 0" xyz="0 0 0"/>
			<geometry>
				<mesh filename="meshes/collision/Indy7_2.stl"/>
			</geometry>
		</collision>
	</link>
	<link name="l_3">
    <inertial>
      <origin rpy="0 0 0" xyz="-0.16804016 0.00021421 -0.07000383"/>
      <mass value="2.68206064"/>
      <inertia ixx="+0.01617210" ixy="-0.00011817" ixz="+0.03341882" iyy="+0.11364055" iyz="-0.00004371" izz="+0.10022522"/>
    </inertial>
		<visual>
			<origin rpy="0 0 0" xyz="0 0 0"/>
			<geometry>
				<mesh filename="meshes/visual/Indy7_3.stl"/>
			</geometry>
		</visual>
		<collision>
			<origin rpy="0 0 0" xyz="0 0 0"/>
			<geometry>
				<mesh filename="meshes/collision/Indy7_3.stl"/>
			</geometry>
		</collision>
	</link>
	<link name="l_4">
	    <inertial>
      <origin rpy="0 0 0" xyz="-0.00026847 -0.07098440 0.07649128"/>
      <mass value="2.12987371"/>
      <inertia ixx="+0.02798891" ixy="+0.00003893" ixz="-0.00004768" iyy="+0.01443076" iyz="-0.01266296" izz="+0.01496211"/>
    </inertial>
		<visual>
			<origin rpy="0 0 0" xyz="0 0 0"/>
			<geometry>
				<mesh filename="meshes/visual/Indy7_4.stl"/>
			</geometry>
		</visual>
		<collision>
			<origin rpy="0 0 0" xyz="0 0 0"/>
			<geometry>
				<mesh filename="meshes/collision/Indy7_4.stl"/>
			</geometry>
		</collision>
	</link>
	<link name="l_5">
	 <inertial>
      <origin rpy="0 0 0" xyz="-0.09796232 -0.00023114 0.06445892"/>
      <mass value="2.22412271"/>
      <inertia ixx="+0.01105297" ixy="+0.00005517" ixz="-0.01481977" iyy="+0.03698291" iyz="-0.00003740" izz="+0.02754795"/>
    </inertial>
		<visual>
			<origin rpy="0 0 0" xyz="0 0 0"/>
			<geometry>
				<mesh filename="meshes/visual/Indy7_5.stl"/>
			</geometry>
		</visual>
		<collision>
			<origin rpy="0 0 0" xyz="0 0 0"/>
			<geometry>
				<mesh filename="meshes/collision/Indy7_5.stl"/>
			</geometry>
		</collision>
	</link>
	<link name="l_6">
		<inertial>
		<origin rpy="0 0 0" xyz="0.00008147 -0.00046556 0.03079097"/>
		<mass value="0.38254932"/>
		<inertia ixx="+0.00078982" ixy="-0.00000034" ixz="+0.00000083" iyy="+0.00079764" iyz="-0.00000508" izz="+0.00058319"/>
		</inertial>
		<visual>
			<origin rpy="0 0 0" xyz="0 0 0"/>
			<geometry>
				<mesh filename="meshes/visual/Indy7_6.stl"/>
			</geometry>
		</visual>
		<collision>
			<origin rpy="0 0 0" xyz="0 0 0"/>
			<geometry>
				<mesh filename="meshes/collision/Indy7_6.stl"/>
			</geometry>
		</collision>
	</link>
	<link name="l_tcp">
	    <!-- <visual>
	      <origin rpy="1.570796 0 0" xyz="0 0 0"/>
	      <geometry>
		<mesh filename="meshes/visual/axis.obj" scale="0.01 0.01 0.01"/>
	      </geometry>	        
	    </visual> -->
		
		
	    <inertial>
	      <mass value="0"/>
	      <origin rpy="0 0 0" xyz="0.0 0.0 0.0"/>
	      <inertia ixx="0.0" ixy="0.0" ixz="0.0" iyy="0.0" iyz="0.0" izz="0.0"/>
	    </inertial>	
	</link>
	<link name="r_tcp">	
	    <!-- <visual>
	      <origin rpy="1.570796 0 0" xyz="0 0 0"/>
	      <geometry>
		<mesh filename="meshes/visual/axis.obj" scale="0.01 0.01 0.01"/>
	      </geometry>	        
	    </visual>
		 -->
		
	    <inertial>
	      <mass value="0"/>
	      <origin rpy="0 0 0" xyz="0.0 0.0 0.0"/>
	      <inertia ixx="0.0" ixy="0.0" ixz="0.0" iyy="0.0" iyz="0.0" izz="0.0"/>
	    </inertial>	
	</link>	
		
 	<joint name="world_fixed" type="fixed">
 		<origin rpy="0 0 0" xyz="0 0 0"/>
 		<parent link="world"/>
		<child link="body"/>
 	</joint>
		<joint name="l_body_fixed" type="fixed">
 		<origin rpy="-2.091 0 0" xyz="0 0.1551 1.2924"/>
		<axis xyz="0 0 1"/>
 		<parent link="body"/>
		<child link="l_0"/>
 	</joint> 	 
 	<joint name="r_body_fixed" type="fixed">   
 		<origin rpy=" 2.091 0 0" xyz="0 -0.1551 1.2924"/>
		<axis xyz="0 0 1"/>
 		<parent link="body"/>
		<child link="r_0"/>
 	</joint> 	
 	
	<joint name="l_joint_0" type="revolute">
    <parent link="l_0"/>
    <child link="l_1"/>
    <origin rpy="0 0 0" xyz="0 0 0.0775"/>
    <axis xyz="0 0 1"/>
    <limit effort="431.97" lower="-3.05432619099" upper="3.05432619099" velocity="2.61799333"/>
  </joint>
  <joint name="l_joint_1" type="revolute">
    <parent link="l_1"/>
    <child link="l_2"/>
    <origin rpy="1.570796327 1.570796327 0" xyz="0 -0.109 0.222"/>
    <axis xyz="0 0 1"/>
    <limit effort="431.97" lower="-3.05432619099" upper="3.05432619099" velocity="2.61799388"/>
</joint>
<joint name="l_joint_2" type="revolute">
    <parent link="l_2"/>
    <child link="l_3"/>
    <origin rpy="0 0 0" xyz="-0.45 0 -0.0305"/>
    <axis xyz="0 0 1"/>
    <limit effort="197.23" lower="-3.05432619099" upper="3.05432619099" velocity="2.61799388"/>
</joint>
<joint name="l_joint_3" type="revolute">
    <parent link="l_3"/>
    <child link="l_4"/>
    <origin rpy="-1.570796327 0 1.570796327" xyz="-0.267 0 -0.075"/>
    <axis xyz="0 0 1"/>
    <limit effort="79.79" lower="-3.05432619099" upper="3.05432619099" velocity="3.14159265"/>
</joint>
<joint name="l_joint_4" type="revolute">
    <parent link="l_4"/>
    <child link="l_5"/>
    <origin rpy="1.570796327 1.570796327 0" xyz="0 -0.114 0.083"/>
    <axis xyz="0 0 1"/>
    <limit effort="79.79" lower="-3.05432619099" upper="3.05432619099" velocity="3.14159265"/>
</joint>
<joint name="l_joint_5" type="revolute">
    <parent link="l_5"/>
    <child link="l_6"/>
    <origin rpy="-1.570796327 0 1.570796327" xyz="-0.168 0 0.069"/>
    <axis xyz="0 0 1"/>
    <limit effort="79.79" lower="-3.75245789179" upper="3.75245789179" velocity="3.14159265"/>
</joint>




	<joint name="r_joint_0" type="revolute">
    <parent link="r_0"/>
    <child link="r_1"/>
    <origin rpy="0 0 0" xyz="0 0 0.0775"/>
    <axis xyz="0 0 1"/>
    <limit effort="431.97" lower="-3.05432619099" upper="3.05432619099" velocity="2.61799333"/>
  </joint>
  <joint name="r_joint_1" type="revolute">
    <parent link="r_1"/>
    <child link="r_2"/>
    <origin rpy="1.570796327 1.570796327 0" xyz="0 -0.109 0.222"/>
    <axis xyz="0 0 1"/>
    <limit effort="431.97" lower="-3.05432619099" upper="3.05432619099" velocity="2.61799388"/>
</joint>
<joint name="r_joint_2" type="revolute">
    <parent link="r_2"/>
    <child link="r_3"/>
    <origin rpy="0 0 0" xyz="-0.45 0 -0.0305"/>
    <axis xyz="0 0 1"/>
    <limit effort="197.23" lower="-3.05432619099" upper="3.05432619099" velocity="2.61799388"/>
</joint>
<joint name="r_joint_3" type="revolute">
    <parent link="r_3"/>
    <child link="r_4"/>
    <origin rpy="-1.570796327 0 1.570796327" xyz="-0.267 0 -0.075"/>
    <axis xyz="0 0 1"/>
    <limit effort="79.79" lower="-3.05432619099" upper="3.05432619099" velocity="3.14159265"/>
</joint>
<joint name="r_joint_4" type="revolute">
    <parent link="r_4"/>
    <child link="r_5"/>
    <origin rpy="1.570796327 1.570796327 0" xyz="0 -0.114 0.083"/>
    <axis xyz="0 0 1"/>
    <limit effort="79.79" lower="-3.05432619099" upper="3.05432619099" velocity="3.14159265"/>
</joint>
<joint name="r_joint_5" type="revolute">
    <parent link="r_5"/>
    <child link="r_6"/>
    <origin rpy="-1.570796327 0 1.570796327" xyz="-0.168 0 0.069"/>
    <axis xyz="0 0 1"/>
    <limit effort="79.79" lower="-3.75245789179" upper="3.75245789179" velocity="3.14159265"/>
</joint>
	<joint name="l_joint_tcp" type="fixed">
		<parent link="l_6"/>
		<child link="l_tcp"/>
		<origin rpy="0.0 0.0 0.0" xyz="0 0 0.06"/>
	</joint>  	
	<joint name="r_joint_tcp" type="fixed">
		<parent link="r_6"/>
		<child link="r_tcp"/>
		<origin rpy="0.0 0.0 0.0" xyz="0 0 0.06"/>
	</joint>  	
	
</robot>
