<?xml version="1.0" ?>
<!-- =================================================================================== -->
<!-- |    This document was autogenerated by xacro from indy7.xacro                    | -->
<!-- |    EDITING THIS FILE BY HAND IS NOT RECOMMENDED                                 | -->
<!-- =================================================================================== -->
<robot name="indy7" xmlns:xacro="http://ros.org/wiki/xacro">
  <!-- <material name="grey"> <color rgba="0.5 0.5 0.5 1"/> </material> -->
    <material name="metal_grey">
      <color rgba="1.0 1.0 1.0 1.0"/> 
  </material>
  <link name="world"/>

  <link name="link0">
    <visual>
      <origin rpy="0 0 0" xyz="0 0 0"/>
      <geometry>
        <mesh filename="meshes/visual/Indy7_0.stl"/>
      </geometry>
      <material name="metal_grey"/>
    </visual>
    <collision>
      <origin rpy="0 0 0" xyz="0 0 0"/>
      <geometry>
        <mesh filename="meshes/collision/Indy7_0.stl"/>
      </geometry>
    </collision>
    <inertial>
      <origin rpy="0 0 0" xyz="0.00131966  -0.00000218  0.03212832"/>
      <mass value="1.6703078"/>
      <inertia ixx="+0.00661309" ixy="+0.00000183" ixz="+0.00002695" iyy="+0.00644765" iyz="-0.00000027" izz="+0.00792090"/>
    </inertial>
  </link>

  <link name="link1">
    <visual>
      <origin rpy="0 0 0" xyz="0 0 0"/>
      <geometry>
        <mesh filename="meshes/visual/Indy7_1.stl"/>
      </geometry>
      <material name="metal_grey"/>
    </visual>
    <collision>
      <origin rpy="0 0 0" xyz="0 0 0.0"/>
      <geometry>
        <mesh filename="meshes/visual/Indy7_1.stl"/>
      </geometry>
    </collision>
    <inertial>
      <origin rpy="0 0 0" xyz="-0.00023749  -0.04310313  0.13245396"/>
      <mass value="11.44444535"/>
      <inertia ixx="+0.35065005" ixy="+0.00011931" ixz="-0.00037553" iyy="+0.30479800" iyz="-0.10984447" izz="+0.06003147"/>
    </inertial>
  </link>



  <link name="link2">
    <visual>
      <origin rpy="0 0 0" xyz="0 0 0"/>
      <geometry>
        <mesh filename="meshes/visual/Indy7_2.stl"/>
      </geometry>
      <material name="metal_grey"/>
    </visual>
    <collision>
      <origin rpy="0 0 0" xyz="0 0 0"/>
      <geometry>
        <mesh filename="meshes/collision/Indy7_2.stl"/>
      </geometry>
    </collision>
    <inertial>
      <origin rpy="0 0 0" xyz="-0.29616699 0.00002254 0.04483069"/>
      <mass value="5.84766553"/>
      <inertia ixx="+0.03599743" ixy="-0.00004693" ixz="-0.05240346" iyy="+0.72293306" iyz="+0.00000176" izz="+0.70024119"/>
    </inertial>
  </link>

  <link name="link3">
    <visual>
      <origin rpy="0 0 0" xyz="0 0 0"/>
      <geometry>
        <mesh filename="meshes/visual/Indy7_3.stl"/>
      </geometry>
      <material name="metal_grey"/>
    </visual>
    <collision>
      <origin rpy="0 0 0" xyz="0 0 0"/>
      <geometry>
        <mesh filename="meshes/collision/Indy7_3.stl"/>
      </geometry>
    </collision>
    <inertial>
      <origin rpy="0 0 0" xyz="-0.16804016 0.00021421 -0.07000383"/>
      <mass value="2.68206064"/>
      <inertia ixx="+0.01617210" ixy="-0.00011817" ixz="+0.03341882" iyy="+0.11364055" iyz="-0.00004371" izz="+0.10022522"/>
    </inertial>
  </link>
  <link name="link4">
    <visual>
      <origin rpy="0 0 0" xyz="0 0 0"/>
      <geometry>
        <mesh filename="meshes/visual/Indy7_4.stl"/>
      </geometry>
      <material name="metal_grey"/>
    </visual>
    <collision>
      <origin rpy="0 0 0" xyz="0 0 0"/>
      <geometry>
        <mesh filename="meshes/collision/Indy7_4.stl"/>
      </geometry>
    </collision>
    <inertial>
      <origin rpy="0 0 0" xyz="-0.00026847 -0.07098440 0.07649128"/>
      <mass value="2.12987371"/>
      <inertia ixx="+0.02798891" ixy="+0.00003893" ixz="-0.00004768" iyy="+0.01443076" iyz="-0.01266296" izz="+0.01496211"/>
    </inertial>
  </link>
  
  <link name="link5">
    <visual>
      <origin rpy="0 0 0" xyz="0 0 0"/>
      <geometry>
        <mesh filename="meshes/visual/Indy7_5.stl"/>
      </geometry>
      <material name="metal_grey"/>
    </visual>
    <collision>
      <origin rpy="0 0 0" xyz="0 0 0"/>
      <geometry>
        <mesh filename="meshes/collision/Indy7_5.stl"/>
      </geometry>
    </collision>
    <inertial>
      <origin rpy="0 0 0" xyz="-0.09796232 -0.00023114 0.06445892"/>
      <mass value="2.22412271"/>
      <inertia ixx="+0.01105297" ixy="+0.00005517" ixz="-0.01481977" iyy="+0.03698291" iyz="-0.00003740" izz="+0.02754795"/>
    </inertial>
  </link>
  
  <link name="link6">
    <visual>
      <origin rpy="0 0 0" xyz="0 0 0"/>
      <geometry>
        <mesh filename="meshes/visual/Indy7_6.stl"/>
      </geometry>
      <material name="metal_grey"/>
    </visual>
    <collision>
      <origin rpy="0 0 0" xyz="0 0 0"/>
      <geometry>
        <mesh filename="meshes/collision/Indy7_6.stl"/>
      </geometry>
    </collision>
    <inertial>
      <origin rpy="0 0 0" xyz="0.00008147 -0.00046556 0.03079097"/>
      <mass value="0.38254932"/>
      <inertia ixx="+0.00078982" ixy="-0.00000034" ixz="+0.00000083" iyy="+0.00079764" iyz="-0.00000508" izz="+0.00058319"/>
    </inertial>
  </link>

  <link name="tcp">
    <collision>
      <geometry>
        <box size="0.01 0.01 0.01" />
      </geometry>
      <origin rpy="0 0 0" xyz="0 0 0" />
    </collision>
    <inertial>
      <mass value="0.00001" />
      <origin rpy="0 0 0" xyz="0.0 0.0 0.0" />
      <inertia ixx="0.0" ixy="0.0" ixz="0.0" iyy="0.0" iyz="0.0" izz="0.0" />
    </inertial>
  </link>

  <joint name="world_joint" type="fixed">
    <parent link="world"/>
    <child link="link0"/>
    <origin rpy="0.0 0.0 0.0" xyz="0 0 0"/>
  </joint>
  <joint name="joint0" type="revolute">
    <parent link="link0"/>
    <child link="link1"/>
    <origin rpy="0 0 0" xyz="0 0 0.0775"/>
    <axis xyz="0 0 1"/>
    <limit effort="431.97" lower="-3.05432619099" upper="3.05432619099" velocity="2.61799333"/>
  </joint>
  <joint name="joint1" type="revolute">
    <parent link="link1"/>
    <child link="link2"/>
    <origin rpy="1.570796327 1.570796327 0" xyz="0 -0.109 0.222"/>
    <axis xyz="0 0 1"/>
    <limit effort="431.97" lower="-3.05432619099" upper="3.05432619099" velocity="2.61799388"/>
</joint>
<joint name="joint2" type="revolute">
    <parent link="link2"/>
    <child link="link3"/>
    <origin rpy="0 0 0" xyz="-0.45 0 -0.0305"/>
    <axis xyz="0 0 1"/>
    <limit effort="197.23" lower="-3.05432619099" upper="3.05432619099" velocity="2.61799388"/>
</joint>
<joint name="joint3" type="revolute">
    <parent link="link3"/>
    <child link="link4"/>
    <origin rpy="-1.570796327 0 1.570796327" xyz="-0.267 0 -0.075"/>
    <axis xyz="0 0 1"/>
    <limit effort="79.79" lower="-3.05432619099" upper="3.05432619099" velocity="3.14159265"/>
</joint>
<joint name="joint4" type="revolute">
    <parent link="link4"/>
    <child link="link5"/>
    <origin rpy="1.570796327 1.570796327 0" xyz="0 -0.114 0.083"/>
    <axis xyz="0 0 1"/>
    <limit effort="79.79" lower="-3.05432619099" upper="3.05432619099" velocity="3.14159265"/>
</joint>
<joint name="joint5" type="revolute">
    <parent link="link5"/>
    <child link="link6"/>
    <origin rpy="-1.570796327 0 1.570796327" xyz="-0.168 0 0.069"/>
    <axis xyz="0 0 1"/>
    <limit effort="79.79" lower="-3.75245789179" upper="3.75245789179" velocity="3.14159265"/>
</joint>

<joint name="tcp" type="fixed">
    <parent link="link6"/>
    <child link="tcp"/>
    <origin rpy="0 0 0" xyz="0 0 0.06"/>
</joint>



</robot>
